Workbook

Sheet 2nd Batch rcvd 08.2025
A1: PO NO. | B1: Color | C1: W (inch) | D1: L (inch) | E1: W (mm) | F1: L (mm) | G1: NOS | H1: m2
A2: 24045976 | B2: ASC 0096-Glossy Black | C2: 49 | D2: 96 | E2: 1245 | F2: 2440 | G2: 2000 | H2: 6075.6
A3: 24045976 | B3: ASC 0096-Glossy Black | C3: 49 | D3: 108 | E3: 1245 | F3: 2745 | G3: 600 | H3: 2050.515
A4: 24045985 | B4: ASC 0096-Glossy Black | C4: 49 | D4: 96 | E4: 1245 | F4: 2440 | G4: 800 | H4: 2430.24
A5: 24045985 | B5: ASC 0069-Glossy White | C5: 49 | D5: 96 | E5: 1245 | F5: 2440 | G5: 800 | H5: 2430.24
A6: 24045985 | B6: AMC 0103-Silver Frost | C6: 49 | D6: 96 | E6: 1245 | F6: 2440 | G6: 600 | H6: 1822.68
A7: 24045985 | B7: AMC 0086-Charcoal Metallic | C7: 49 | D7: 96 | E7: 1245 | F7: 2440 | G7: 600 | H7: 1822.68
A8: 24045987 | B8: ASC 0096-Glossy Black | C8: 49 | D8: 96 | E8: 1245 | F8: 2440 | G8: 200 | H8: 607.56
A9: 24045987 | B9: ASC 0096-Glossy Black | C9: 49 | D9: 108 | E9: 1245 | F9: 2745 | G9: 400 | H9: 1367.01
A10: 24045987 | B10: ASC 0069-Glossy White | C10: 49 | D10: 96 | E10: 1245 | F10: 2440 | G10: 800 | H10: 2430.24
A11: 24045987 | B11: ASC 0069-Glossy White | C11: 49 | D11: 108 | E11: 1245 | F11: 2745 | G11: 400 | H11: 1367.01
A12: 24045987 | B12: AMC 0103-Silver Frost | C12: 49 | D12: 96 | E12: 1245 | F12: 2440 | G12: 200 | H12: 607.56
A13: 24045987 | B13: AMC 0103-Silver Frost | C13: 49 | D13: 108 | E13: 1245 | F13: 2745 | G13: 200 | H13: 683.505
... A58: 52923929 | B58: AMC 0086-Charcoal Metallic | C58: 49 | D58: 108 | E58: 1245 | F58: 2745 | G58: 400 | H58: 1367.01
G59: =SUM(G2:G58) -> 34000 | H59: =SUM(H2:H58) -> 108825.45

Sheet Dashboard
Q2: TOTAL VOLUME
C3: ORDER STATUS (ACTIVE ONLY) | D3: South Paris, ME | E3: Ashburn, GA | F3: Hillsboro, TX | G3: Nampa, ID | H3: Granger, IN | I3: Gordon, PA | J3: Minneota, MN | K3: Houston, TX | L3: Twin Falls, ID | M3: Savannah, GA | N3: TOTALS | Q3: COLORS (Purple are Standard Colors) | R3: Sheets | S3: MSF | T3: M2 | U3: $
C4: PO Received | D4: =COUNTIFS('Order Summary'!$G:$G,"Yes",'Order Summary'!$I:$I,Dashboard!D$3,'Order Summary'!$E:$E,Dashboard!$C4) -> 1 | E4: =COUNTIFS('Order Summary'!$G:$G,"Yes",'Order Summary'!$I:$I,Dashboard!E$3,'Order Summary'!$E:$E,Dashboard!$C4) -> 0 | F4: =COUNTIFS('Order Summary'!$G:$G,"Yes",'Order Summary'!$I:$I,Dashboard!F$3,'Order Summary'!$E:$E,Dashboard!$C4) -> 8 | G4: =COUNTIFS('Order Summary'!$G:$G,"Yes",'Order Summary'!$I:$I,Dashboard!G$3,'Order Summary'!$E:$E,Dashboard!$C4) -> 2 | H4: =COUNTIFS('Order Summary'!$G:$G,"Yes",'Order Summary'!$I:$I,Dashboard!H$3,'Order Summary'!$E:$E,Dashboard!$C4) -> 5 | I4: =COUNTIFS('Order Summary'!$G:$G,"Yes",'Order Summary'!$I:$I,Dashboard!I$3,'Order Summary'!$E:$E,Dashboard!$C4) -> 1 | J4: =COUNTIFS('Order Summary'!$G:$G,"Yes",'Order Summary'!$I:$I,Dashboard!J$3,'Order Summary'!$E:$E,Dashboard!$C4) -> 6 | K4: =COUNTIFS('Order Summary'!$G:$G,"Yes",'Order Summary'!$I:$I,Dashboard!K$3,'Order Summary'!$E:$E,Dashboard!$C4) -> 0 | ... M4: =COUNTIFS('Order Summary'!$G:$G,"Yes",'Order Summary'!$I:$I,Dashboard!M$3,'Order Summary'!$E:$E,Dashboard!$C4) -> 0 | N4: =SUM(D4:M4) -> 24 | Q4: ASC 0096 GLOSSY BLACK | R4: =SUMIFS('Order Details'!$Q:$Q,'Order Details'!$N:$N,Dashboard!$Q4,'Order Details'!$E:$E,"Yes") -> 87500 | S4: =SUMIFS('Order Details'!$O:$O,'Order Details'!$N:$N,Dashboard!$Q4,'Order Details'!$E:$E,"Yes") -> 3060.12 | T4: =SUMIFS('Order Details'!$P:$P,'Order Details'!$N:$N,Dashboard!$Q4,'Order Details'!$E:$E,"Yes") -> 281970.21 | U4: =SUMIFS('Order Details'!$V:$V,'Order Details'!$N:$N,Dashboard!$Q4,'Order Details'!$E:$E,"Yes") -> 2144825.6 | AB4: Purchase Order to Proforma Invoice:
C5: Proforma Invoice Sent | D5: =COUNTIFS('Order Summary'!$G:$G,"Yes",'Order Summary'!$I:$I,Dashboard!D$3,'Order Summary'!$E:$E,Dashboard!$C5) -> 2 | E5: =COUNTIFS('Order Summary'!$G:$G,"Yes",'Order Summary'!$I:$I,Dashboard!E$3,'Order Summary'!$E:$E,Dashboard!$C5) -> 0 | F5: =COUNTIFS('Order Summary'!$G:$G,"Yes",'Order Summary'!$I:$I,Dashboard!F$3,'Order Summary'!$E:$E,Dashboard!$C5) -> 1 | G5: =COUNTIFS('Order Summary'!$G:$G,"Yes",'Order Summary'!$I:$I,Dashboard!G$3,'Order Summary'!$E:$E,Dashboard!$C5) -> 0 | H5: =COUNTIFS('Order Summary'!$G:$G,"Yes",'Order Summary'!$I:$I,Dashboard!H$3,'Order Summary'!$E:$E,Dashboard!$C5) -> 0 | I5: =COUNTIFS('Order Summary'!$G:$G,"Yes",'Order Summary'!$I:$I,Dashboard!I$3,'Order Summary'!$E:$E,Dashboard!$C5) -> 10 | J5: =COUNTIFS('Order Summary'!$G:$G,"Yes",'Order Summary'!$I:$I,Dashboard!J$3,'Order Summary'!$E:$E,Dashboard!$C5) -> 0 | K5: =COUNTIFS('Order Summary'!$G:$G,"Yes",'Order Summary'!$I:$I,Dashboard!K$3,'Order Summary'!$E:$E,Dashboard!$C5) -> 0 | ... M5: =COUNTIFS('Order Summary'!$G:$G,"Yes",'Order Summary'!$I:$I,Dashboard!M$3,'Order Summary'!$E:$E,Dashboard!$C5) -> 0 | N5: =SUM(D5:M5) -> 13 | Q5: ASC 0069 GLOSSY WHITE | R5: =SUMIFS('Order Details'!$Q:$Q,'Order Details'!$N:$N,Dashboard!$Q5,'Order Details'!$E:$E,"Yes") -> 121850 | S5: =SUMIFS('Order Details'!$O:$O,'Order Details'!$N:$N,Dashboard!$Q5,'Order Details'!$E:$E,"Yes") -> 4169.1193 | T5: =SUMIFS('Order Details'!$P:$P,'Order Details'!$N:$N,Dashboard!$Q5,'Order Details'!$E:$E,"Yes") -> 387377.83 | U5: =SUMIFS('Order Details'!$V:$V,'Order Details'!$N:$N,Dashboard!$Q5,'Order Details'!$E:$E,"Yes") -> 2958298.3 | AB5: Average Days: | AC5: =AVERAGEIFS('Order Summary'!$O$4:$O$200,'Order Summary'!$O$4:$O$200,"<>"&"",'Order Summary'!$G$4:$G$200,"Yes") -> 7.6058394
C6: Downpayment Received | D6: =COUNTIFS('Order Summary'!$G:$G,"Yes",'Order Summary'!$I:$I,Dashboard!D$3,'Order Summary'!$E:$E,Dashboard!$C6) -> 0 | E6: =COUNTIFS('Order Summary'!$G:$G,"Yes",'Order Summary'!$I:$I,Dashboard!E$3,'Order Summary'!$E:$E,Dashboard!$C6) -> 3 | F6: =COUNTIFS('Order Summary'!$G:$G,"Yes",'Order Summary'!$I:$I,Dashboard!F$3,'Order Summary'!$E:$E,Dashboard!$C6) -> 2 | G6: =COUNTIFS('Order Summary'!$G:$G,"Yes",'Order Summary'!$I:$I,Dashboard!G$3,'Order Summary'!$E:$E,Dashboard!$C6) -> 11 | H6: =COUNTIFS('Order Summary'!$G:$G,"Yes",'Order Summary'!$I:$I,Dashboard!H$3,'Order Summary'!$E:$E,Dashboard!$C6) -> 3 | I6: =COUNTIFS('Order Summary'!$G:$G,"Yes",'Order Summary'!$I:$I,Dashboard!I$3,'Order Summary'!$E:$E,Dashboard!$C6) -> 1 | J6: =COUNTIFS('Order Summary'!$G:$G,"Yes",'Order Summary'!$I:$I,Dashboard!J$3,'Order Summary'!$E:$E,Dashboard!$C6) -> 0 | K6: =COUNTIFS('Order Summary'!$G:$G,"Yes",'Order Summary'!$I:$I,Dashboard!K$3,'Order Summary'!$E:$E,Dashboard!$C6) -> 0 | ... M6: =COUNTIFS('Order Summary'!$G:$G,"Yes",'Order Summary'!$I:$I,Dashboard!M$3,'Order Summary'!$E:$E,Dashboard!$C6) -> 0 | N6: =SUM(D6:M6) -> 21 | Q6: AMC 0103 SILVER FROST | R6: =SUMIFS('Order Details'!$Q:$Q,'Order Details'!$N:$N,Dashboard!$Q6,'Order Details'!$E:$E,"Yes") -> 70650 | S6: =SUMIFS('Order Details'!$O:$O,'Order Details'!$N:$N,Dashboard!$Q6,'Order Details'!$E:$E,"Yes") -> 2449.2863 | T6: =SUMIFS('Order Details'!$P:$P,'Order Details'!$N:$N,Dashboard!$Q6,'Order Details'!$E:$E,"Yes") -> 227447.62 | U6: =SUMIFS('Order Details'!$V:$V,'Order Details'!$N:$N,Dashboard!$Q6,'Order Details'!$E:$E,"Yes") -> 1728889.6 | AB6: POs without PIs: | AC6: =COUNTIFS('Order Summary'!$O$4:$O$200,"",'Order Summary'!$F$4:$F$200,"<>"&"",'Order Summary'!$G$4:$G$200,"Yes") -> 11
C7: In Production | D7: =COUNTIFS('Order Summary'!$G:$G,"Yes",'Order Summary'!$I:$I,Dashboard!D$3,'Order Summary'!$E:$E,Dashboard!$C7) -> 0 | E7: =COUNTIFS('Order Summary'!$G:$G,"Yes",'Order Summary'!$I:$I,Dashboard!E$3,'Order Summary'!$E:$E,Dashboard!$C7) -> 0 | F7: =COUNTIFS('Order Summary'!$G:$G,"Yes",'Order Summary'!$I:$I,Dashboard!F$3,'Order Summary'!$E:$E,Dashboard!$C7) -> 0 | G7: =COUNTIFS('Order Summary'!$G:$G,"Yes",'Order Summary'!$I:$I,Dashboard!G$3,'Order Summary'!$E:$E,Dashboard!$C7) -> 0 | H7: =COUNTIFS('Order Summary'!$G:$G,"Yes",'Order Summary'!$I:$I,Dashboard!H$3,'Order Summary'!$E:$E,Dashboard!$C7) -> 0 | I7: =COUNTIFS('Order Summary'!$G:$G,"Yes",'Order Summary'!$I:$I,Dashboard!I$3,'Order Summary'!$E:$E,Dashboard!$C7) -> 0 | J7: =COUNTIFS('Order Summary'!$G:$G,"Yes",'Order Summary'!$I:$I,Dashboard!J$3,'Order Summary'!$E:$E,Dashboard!$C7) -> 0 | K7: =COUNTIFS('Order Summary'!$G:$G,"Yes",'Order Summary'!$I:$I,Dashboard!K$3,'Order Summary'!$E:$E,Dashboard!$C7) -> 0 | ... M7: =COUNTIFS('Order Summary'!$G:$G,"Yes",'Order Summary'!$I:$I,Dashboard!M$3,'Order Summary'!$E:$E,Dashboard!$C7) -> 2 | N7: =SUM(D7:M7) -> 6 | Q7: AMC 0086 CHARCOAL METALLIC | R7: =SUMIFS('Order Details'!$Q:$Q,'Order Details'!$N:$N,Dashboard!$Q7,'Order Details'!$E:$E,"Yes") -> 66950 | S7: =SUMIFS('Order Details'!$O:$O,'Order Details'!$N:$N,Dashboard!$Q7,'Order Details'!$E:$E,"Yes") -> 2304.3303 | T7: =SUMIFS('Order Details'!$P:$P,'Order Details'!$N:$N,Dashboard!$Q7,'Order Details'!$E:$E,"Yes") -> 213971.61 | U7: =SUMIFS('Order Details'!$V:$V,'Order Details'!$N:$N,Dashboard!$Q7,'Order Details'!$E:$E,"Yes") -> 1739662
C8: Container Loaded | D8: =COUNTIFS('Order Summary'!$G:$G,"Yes",'Order Summary'!$I:$I,Dashboard!D$3,'Order Summary'!$E:$E,Dashboard!$C8) -> 0 | E8: =COUNTIFS('Order Summary'!$G:$G,"Yes",'Order Summary'!$I:$I,Dashboard!E$3,'Order Summary'!$E:$E,Dashboard!$C8) -> 0 | F8: =COUNTIFS('Order Summary'!$G:$G,"Yes",'Order Summary'!$I:$I,Dashboard!F$3,'Order Summary'!$E:$E,Dashboard!$C8) -> 0 | G8: =COUNTIFS('Order Summary'!$G:$G,"Yes",'Order Summary'!$I:$I,Dashboard!G$3,'Order Summary'!$E:$E,Dashboard!$C8) -> 0 | H8: =COUNTIFS('Order Summary'!$G:$G,"Yes",'Order Summary'!$I:$I,Dashboard!H$3,'Order Summary'!$E:$E,Dashboard!$C8) -> 0 | I8: =COUNTIFS('Order Summary'!$G:$G,"Yes",'Order Summary'!$I:$I,Dashboard!I$3,'Order Summary'!$E:$E,Dashboard!$C8) -> 0 | J8: =COUNTIFS('Order Summary'!$G:$G,"Yes",'Order Summary'!$I:$I,Dashboard!J$3,'Order Summary'!$E:$E,Dashboard!$C8) -> 0 | K8: =COUNTIFS('Order Summary'!$G:$G,"Yes",'Order Summary'!$I:$I,Dashboard!K$3,'Order Summary'!$E:$E,Dashboard!$C8) -> 1 | ... M8: =COUNTIFS('Order Summary'!$G:$G,"Yes",'Order Summary'!$I:$I,Dashboard!M$3,'Order Summary'!$E:$E,Dashboard!$C8) -> 2 | N8: =SUM(D8:M8) -> 3 | Q8: ASC 0099 MATTE BLACK | R8: =SUMIFS('Order Details'!$Q:$Q,'Order Details'!$N:$N,Dashboard!$Q8,'Order Details'!$E:$E,"Yes") -> 7800 | S8: =SUMIFS('Order Details'!$O:$O,'Order Details'!$N:$N,Dashboard!$Q8,'Order Details'!$E:$E,"Yes") -> 261.74167 | T8: =SUMIFS('Order Details'!$P:$P,'Order Details'!$N:$N,Dashboard!$Q8,'Order Details'!$E:$E,"Yes") -> 24338.505 | U8: =SUMIFS('Order Details'!$V:$V,'Order Details'!$N:$N,Dashboard!$Q8,'Order Details'!$E:$E,"Yes") -> 196411.74 | AB8: Proforma Invoice to Downpayment:
C9: Commercial Invoice Sent | D9: =COUNTIFS('Order Summary'!$G:$G,"Yes",'Order Summary'!$I:$I,Dashboard!D$3,'Order Summary'!$E:$E,Dashboard!$C9) -> 0 | E9: =COUNTIFS('Order Summary'!$G:$G,"Yes",'Order Summary'!$I:$I,Dashboard!E$3,'Order Summary'!$E:$E,Dashboard!$C9) -> 0 | F9: =COUNTIFS('Order Summary'!$G:$G,"Yes",'Order Summary'!$I:$I,Dashboard!F$3,'Order Summary'!$E:$E,Dashboard!$C9) -> 0 | G9: =COUNTIFS('Order Summary'!$G:$G,"Yes",'Order Summary'!$I:$I,Dashboard!G$3,'Order Summary'!$E:$E,Dashboard!$C9) -> 2 | H9: =COUNTIFS('Order Summary'!$G:$G,"Yes",'Order Summary'!$I:$I,Dashboard!H$3,'Order Summary'!$E:$E,Dashboard!$C9) -> 1 | I9: =COUNTIFS('Order Summary'!$G:$G,"Yes",'Order Summary'!$I:$I,Dashboard!I$3,'Order Summary'!$E:$E,Dashboard!$C9) -> 0 | J9: =COUNTIFS('Order Summary'!$G:$G,"Yes",'Order Summary'!$I:$I,Dashboard!J$3,'Order Summary'!$E:$E,Dashboard!$C9) -> 0 | K9: =COUNTIFS('Order Summary'!$G:$G,"Yes",'Order Summary'!$I:$I,Dashboard!K$3,'Order Summary'!$E:$E,Dashboard!$C9) -> 5 | ... M9: =COUNTIFS('Order Summary'!$G:$G,"Yes",'Order Summary'!$I:$I,Dashboard!M$3,'Order Summary'!$E:$E,Dashboard!$C9) -> 4 | N9: =SUM(D9:M9) -> 13 | Q9: ASC 0092 PEPSI BLUE | R9: =SUMIFS('Order Details'!$Q:$Q,'Order Details'!$N:$N,Dashboard!$Q9,'Order Details'!$E:$E,"Yes") -> 800 | S9: =SUMIFS('Order Details'!$O:$O,'Order Details'!$N:$N,Dashboard!$Q9,'Order Details'!$E:$E,"Yes") -> 28.652 | T9: =SUMIFS('Order Details'!$P:$P,'Order Details'!$N:$N,Dashboard!$Q9,'Order Details'!$E:$E,"Yes") -> 2664.3 | U9: =SUMIFS('Order Details'!$V:$V,'Order Details'!$N:$N,Dashboard!$Q9,'Order Details'!$E:$E,"Yes") -> 20214.069 | AB9: Average Days: | AC9: =AVERAGEIFS('Order Summary'!$R$4:$R$200,'Order Summary'!$R$4:$R$200,"<>"&"",'Order Summary'!$G$4:$G$200,"Yes") -> 30.146789
C10: Balance Payment Received | D10: =COUNTIFS('Order Summary'!$G:$G,"Yes",'Order Summary'!$I:$I,Dashboard!D$3,'Order Summary'!$E:$E,Dashboard!$C10) -> 0 | E10: =COUNTIFS('Order Summary'!$G:$G,"Yes",'Order Summary'!$I:$I,Dashboard!E$3,'Order Summary'!$E:$E,Dashboard!$C10) -> 4 | F10: =COUNTIFS('Order Summary'!$G:$G,"Yes",'Order Summary'!$I:$I,Dashboard!F$3,'Order Summary'!$E:$E,Dashboard!$C10) -> 0 | G10: =COUNTIFS('Order Summary'!$G:$G,"Yes",'Order Summary'!$I:$I,Dashboard!G$3,'Order Summary'!$E:$E,Dashboard!$C10) -> 3 | H10: =COUNTIFS('Order Summary'!$G:$G,"Yes",'Order Summary'!$I:$I,Dashboard!H$3,'Order Summary'!$E:$E,Dashboard!$C10) -> 3 | I10: =COUNTIFS('Order Summary'!$G:$G,"Yes",'Order Summary'!$I:$I,Dashboard!I$3,'Order Summary'!$E:$E,Dashboard!$C10) -> 0 | J10: =COUNTIFS('Order Summary'!$G:$G,"Yes",'Order Summary'!$I:$I,Dashboard!J$3,'Order Summary'!$E:$E,Dashboard!$C10) -> 1 | K10: =COUNTIFS('Order Summary'!$G:$G,"Yes",'Order Summary'!$I:$I,Dashboard!K$3,'Order Summary'!$E:$E,Dashboard!$C10) -> 8 | ... M10: =COUNTIFS('Order Summary'!$G:$G,"Yes",'Order Summary'!$I:$I,Dashboard!M$3,'Order Summary'!$E:$E,Dashboard!$C10) -> 4 | N10: =SUM(D10:M10) -> 23 | Q10: ASC 0089 VICTORY RED | R10: =SUMIFS('Order Details'!$Q:$Q,'Order Details'!$N:$N,Dashboard!$Q10,'Order Details'!$E:$E,"Yes") -> 9400 | S10: =SUMIFS('Order Details'!$O:$O,'Order Details'!$N:$N,Dashboard!$Q10,'Order Details'!$E:$E,"Yes") -> 325.98533 | T10: =SUMIFS('Order Details'!$P:$P,'Order Details'!$N:$N,Dashboard!$Q10,'Order Details'!$E:$E,"Yes") -> 30314.007 | U10: =SUMIFS('Order Details'!$V:$V,'Order Details'!$N:$N,Dashboard!$Q10,'Order Details'!$E:$E,"Yes") -> 231395.9 | AB10: Unpaid PIs: | AC10: =COUNTIFS('Order Summary'!$R$4:$R$200,"",'Order Summary'!$N$4:$N$200,"<>"&"",'Order Summary'!$G$4:$G$200,"Yes") -> 26
C11: Telex / Seaway Released | D11: =COUNTIFS('Order Summary'!$G:$G,"Yes",'Order Summary'!$I:$I,Dashboard!D$3,'Order Summary'!$E:$E,Dashboard!$C11) -> 1 | E11: =COUNTIFS('Order Summary'!$G:$G,"Yes",'Order Summary'!$I:$I,Dashboard!E$3,'Order Summary'!$E:$E,Dashboard!$C11) -> 6 | F11: =COUNTIFS('Order Summary'!$G:$G,"Yes",'Order Summary'!$I:$I,Dashboard!F$3,'Order Summary'!$E:$E,Dashboard!$C11) -> 11 | G11: =COUNTIFS('Order Summary'!$G:$G,"Yes",'Order Summary'!$I:$I,Dashboard!G$3,'Order Summary'!$E:$E,Dashboard!$C11) -> 11 | H11: =COUNTIFS('Order Summary'!$G:$G,"Yes",'Order Summary'!$I:$I,Dashboard!H$3,'Order Summary'!$E:$E,Dashboard!$C11) -> 11 | I11: =COUNTIFS('Order Summary'!$G:$G,"Yes",'Order Summary'!$I:$I,Dashboard!I$3,'Order Summary'!$E:$E,Dashboard!$C11) -> 2 | J11: =COUNTIFS('Order Summary'!$G:$G,"Yes",'Order Summary'!$I:$I,Dashboard!J$3,'Order Summary'!$E:$E,Dashboard!$C11) -> 2 | K11: =COUNTIFS('Order Summary'!$G:$G,"Yes",'Order Summary'!$I:$I,Dashboard!K$3,'Order Summary'!$E:$E,Dashboard!$C11) -> 0 | ... M11: =COUNTIFS('Order Summary'!$G:$G,"Yes",'Order Summary'!$I:$I,Dashboard!M$3,'Order Summary'!$E:$E,Dashboard!$C11) -> 2 | N11: =SUM(D11:M11) -> 46 | Q11: AMC 0104 PEWTER | R11: =SUMIFS('Order Details'!$Q:$Q,'Order Details'!$N:$N,Dashboard!$Q11,'Order Details'!$E:$E,"Yes") -> 0 | S11: =SUMIFS('Order Details'!$O:$O,'Order Details'!$N:$N,Dashboard!$Q11,'Order Details'!$E:$E,"Yes") -> 0 | T11: =SUMIFS('Order Details'!$P:$P,'Order Details'!$N:$N,Dashboard!$Q11,'Order Details'!$E:$E,"Yes") -> 0 | U11: =SUMIFS('Order Details'!$V:$V,'Order Details'!$N:$N,Dashboard!$Q11,'Order Details'!$E:$E,"Yes") -> 0 | AB11: Unpaid Value: | AC11: =SUMIFS('Order Summary'!$P$4:$P$200,'Order Summary'!$R$4:$R$200,"",'Order Summary'!$N$4:$N$200,"<>"&"",'Order Summary'!$G$4:$G$200,"Yes")*'Master Data'!$P$12 -> 843699.41
C12: Arrived | D12: =COUNTIFS('Order Summary'!$G:$G,"Yes",'Order Summary'!$I:$I,Dashboard!D$3,'Order Summary'!$AO:$AO,"<>"&"",'Order Summary'!$AO:$AO,"<>"&"PENDING") -> 1 | E12: =COUNTIFS('Order Summary'!$G:$G,"Yes",'Order Summary'!$I:$I,Dashboard!E$3,'Order Summary'!$AO:$AO,"<>"&"",'Order Summary'!$AO:$AO,"<>"&"PENDING") -> 6 | F12: =COUNTIFS('Order Summary'!$G:$G,"Yes",'Order Summary'!$I:$I,Dashboard!F$3,'Order Summary'!$AO:$AO,"<>"&"",'Order Summary'!$AO:$AO,"<>"&"PENDING") -> 9 | G12: =COUNTIFS('Order Summary'!$G:$G,"Yes",'Order Summary'!$I:$I,Dashboard!G$3,'Order Summary'!$AO:$AO,"<>"&"",'Order Summary'!$AO:$AO,"<>"&"PENDING") -> 9 | H12: =COUNTIFS('Order Summary'!$G:$G,"Yes",'Order Summary'!$I:$I,Dashboard!H$3,'Order Summary'!$AO:$AO,"<>"&"",'Order Summary'!$AO:$AO,"<>"&"PENDING") -> 13 | I12: =COUNTIFS('Order Summary'!$G:$G,"Yes",'Order Summary'!$I:$I,Dashboard!I$3,'Order Summary'!$AO:$AO,"<>"&"",'Order Summary'!$AO:$AO,"<>"&"PENDING") -> 1 | J12: =COUNTIFS('Order Summary'!$G:$G,"Yes",'Order Summary'!$I:$I,Dashboard!J$3,'Order Summary'!$AO:$AO,"<>"&"",'Order Summary'!$AO:$AO,"<>"&"PENDING") -> 3 | K12: =COUNTIFS('Order Summary'!$G:$G,"Yes",'Order Summary'!$I:$I,Dashboard!K$3,'Order Summary'!$AO:$AO,"<>"&"",'Order Summary'!$AO:$AO,"<>"&"PENDING") -> 0 | ... M12: =COUNTIFS('Order Summary'!$G:$G,"Yes",'Order Summary'!$I:$I,Dashboard!M$3,'Order Summary'!$AO:$AO,"<>"&"",'Order Summary'!$AO:$AO,"<>"&"PENDING") -> 2 | N12: =SUM(D12:M12) -> 44 | Q12: ASC 0105 INDIGO BLUE | R12: =SUMIFS('Order Details'!$Q:$Q,'Order Details'!$N:$N,Dashboard!$Q12,'Order Details'!$E:$E,"Yes") -> 8950 | S12: =SUMIFS('Order Details'!$O:$O,'Order Details'!$N:$N,Dashboard!$Q12,'Order Details'!$E:$E,"Yes") -> 306.18033 | T12: =SUMIFS('Order Details'!$P:$P,'Order Details'!$N:$N,Dashboard!$Q12,'Order Details'!$E:$E,"Yes") -> 28472.341 | U12: =SUMIFS('Order Details'!$V:$V,'Order Details'!$N:$N,Dashboard!$Q12,'Order Details'!$E:$E,"Yes") -> 232869.04
C13: TOTALS | D13: =SUM(D4:D11) -> 4 | E13: =SUM(E4:E11) -> 13 | F13: =SUM(F4:F11) -> 22 | G13: =SUM(G4:G11) -> 29 | H13: =SUM(H4:H11) -> 23 | I13: =SUM(I4:I11) -> 14 | J13: =SUM(J4:J11) -> 9 | K13: =SUM(K4:K11) -> 14 | ... N13: =SUM(N4:N11) -> 149 | Q13: ASC 0164 ARMY GREEN | R13: =SUMIFS('Order Details'!$Q:$Q,'Order Details'!$N:$N,Dashboard!$Q13,'Order Details'!$E:$E,"Yes") -> 4200 | S13: =SUMIFS('Order Details'!$O:$O,'Order Details'!$N:$N,Dashboard!$Q13,'Order Details'!$E:$E,"Yes") -> 139.343 | T13: =SUMIFS('Order Details'!$P:$P,'Order Details'!$N:$N,Dashboard!$Q13,'Order Details'!$E:$E,"Yes") -> 12957.213 | U13: =SUMIFS('Order Details'!$V:$V,'Order Details'!$N:$N,Dashboard!$Q13,'Order Details'!$E:$E,"Yes") -> 106305.72 | AB13: Downpayment to Actual Shipping Departure:
Q14: ASC 0127 SAND SAHARA | R14: =SUMIFS('Order Details'!$Q:$Q,'Order Details'!$N:$N,Dashboard!$Q14,'Order Details'!$E:$E,"Yes") -> 1400 | S14: =SUMIFS('Order Details'!$O:$O,'Order Details'!$N:$N,Dashboard!$Q14,'Order Details'!$E:$E,"Yes") -> 45.733 | T14: =SUMIFS('Order Details'!$P:$P,'Order Details'!$N:$N,Dashboard!$Q14,'Order Details'!$E:$E,"Yes") -> 4252.173 | U14: =SUMIFS('Order Details'!$V:$V,'Order Details'!$N:$N,Dashboard!$Q14,'Order Details'!$E:$E,"Yes") -> 34315.036 | AB14: Average Days: | AC14: =AVERAGEIFS('Order Summary'!$AB$4:$AB$200,'Order Summary'!$AB$4:$AB$200,"<>"&"",'Order Summary'!$G$4:$G$200,"Yes") -> 67.821429
Q15: ASC 0208 SAND SAHARA MATTE | R15: =SUMIFS('Order Details'!$Q:$Q,'Order Details'!$N:$N,Dashboard!$Q15,'Order Details'!$E:$E,"Yes") -> 2400 | S15: =SUMIFS('Order Details'!$O:$O,'Order Details'!$N:$N,Dashboard!$Q15,'Order Details'!$E:$E,"Yes") -> 80.169 | T15: =SUMIFS('Order Details'!$P:$P,'Order Details'!$N:$N,Dashboard!$Q15,'Order Details'!$E:$E,"Yes") -> 7455.06 | U15: =SUMIFS('Order Details'!$V:$V,'Order Details'!$N:$N,Dashboard!$Q15,'Order Details'!$E:$E,"Yes") -> 61653.346 | AB15: DP Received, Unshipped: | AC15: =COUNTIFS('Order Summary'!$Q4:$Q200,"<>"&"",'Order Summary'!$AA4:$AA200,"",'Order Summary'!$G$4:$G$200,"Yes") -> 36
C16: Open Orders | D16: =SUM(D4:D7) -> 3 | E16: =SUM(E4:E7) -> 3 | F16: =SUM(F4:F7) -> 11 | G16: =SUM(G4:G7) -> 13 | H16: =SUM(H4:H7) -> 8 | I16: =SUM(I4:I7) -> 12 | J16: =SUM(J4:J7) -> 6 | K16: =SUM(K4:K7) -> 0 | ... N16: =SUM(N4:N7) -> 64 | Q16: ASC 0090 YELLOW | R16: =SUMIFS('Order Details'!$Q:$Q,'Order Details'!$N:$N,Dashboard!$Q16,'Order Details'!$E:$E,"Yes") -> 0 | S16: =SUMIFS('Order Details'!$O:$O,'Order Details'!$N:$N,Dashboard!$Q16,'Order Details'!$E:$E,"Yes") -> 0 | T16: =SUMIFS('Order Details'!$P:$P,'Order Details'!$N:$N,Dashboard!$Q16,'Order Details'!$E:$E,"Yes") -> 0 | U16: =SUMIFS('Order Details'!$V:$V,'Order Details'!$N:$N,Dashboard!$Q16,'Order Details'!$E:$E,"Yes") -> 0
C17: Shipped | D17: =SUM(D8:D11)-D12 -> 0 | E17: =SUM(E8:E11)-E12 -> 4 | F17: =SUM(F8:F11)-F12 -> 2 | G17: =SUM(G8:G11)-G12 -> 7 | H17: =SUM(H8:H11)-H12 -> 2 | I17: =SUM(I8:I11)-I12 -> 1 | J17: =SUM(J8:J11)-J12 -> 0 | K17: =SUM(K8:K11)-K12 -> 14 | ... N17: =SUM(N8:N11)-N12 -> 41 | Q17: ASC 0091 ORANGE | R17: =SUMIFS('Order Details'!$Q:$Q,'Order Details'!$N:$N,Dashboard!$Q17,'Order Details'!$E:$E,"Yes") -> 0 | S17: =SUMIFS('Order Details'!$O:$O,'Order Details'!$N:$N,Dashboard!$Q17,'Order Details'!$E:$E,"Yes") -> 0 | T17: =SUMIFS('Order Details'!$P:$P,'Order Details'!$N:$N,Dashboard!$Q17,'Order Details'!$E:$E,"Yes") -> 0 | U17: =SUMIFS('Order Details'!$V:$V,'Order Details'!$N:$N,Dashboard!$Q17,'Order Details'!$E:$E,"Yes") -> 0 | AB17: Commercial Invoice to Balance Payment:
C18: Arrived | D18: =D12 -> 1 | E18: =E12 -> 6 | F18: =F12 -> 9 | G18: =G12 -> 9 | H18: =H12 -> 13 | I18: =I12 -> 1 | J18: =J12 -> 3 | K18: =K12 -> 0 | ... N18: =N12 -> 44 | Q18: ASC 0126 BRANDY WINE | R18: =SUMIFS('Order Details'!$Q:$Q,'Order Details'!$N:$N,Dashboard!$Q18,'Order Details'!$E:$E,"Yes") -> 0 | S18: =SUMIFS('Order Details'!$O:$O,'Order Details'!$N:$N,Dashboard!$Q18,'Order Details'!$E:$E,"Yes") -> 0 | T18: =SUMIFS('Order Details'!$P:$P,'Order Details'!$N:$N,Dashboard!$Q18,'Order Details'!$E:$E,"Yes") -> 0 | U18: =SUMIFS('Order Details'!$V:$V,'Order Details'!$N:$N,Dashboard!$Q18,'Order Details'!$E:$E,"Yes") -> 0 | AB18: Average Days: | AC18: =AVERAGEIFS('Order Summary'!$AK$4:$AK$200,'Order Summary'!$AK$4:$AK$200,"<>"&"",'Order Summary'!$G$4:$G$200,"Yes") -> 19.03125
Q19: TOTALS | R19: =SUM(R4:R18) -> 381900 | S19: =SUM(S4:S18) -> 13170.66 | T19: =SUM(T4:T18) -> 1221220.9 | U19: =SUM(U4:U18) -> 9454840.3 | AB19: Unpaid CIs: | AC19: =COUNTIFS('Order Summary'!$AK$4:$AK$200,"",'Order Summary'!$AD$4:$AD$200,"<>"&"",'Order Summary'!$G$4:$G$200,"Yes") -> 19
AB20: Unpaid Value: | AC20: =SUMIFS('Order Summary'!$AI$4:$AI$200,'Order Summary'!$AK$4:$AK$200,"",'Order Summary'!$AD$4:$AD$200,"<>"&"",'Order Summary'!$G$4:$G$200,"Yes") -> 758670.85
Q22: VOLUME ON ORDER (NOT SHIPPED) | AB22: Balance Payment to Telex/Seaway Release:
Q23: COLORS (Purple are Standard Colors) | R23: Sheets | S23: MSF | T23: M2 | U23: $ | AB23: Average Days: | AC23: =AVERAGEIFS('Order Summary'!$AN$4:$AN$200,'Order Summary'!$AN$4:$AN$200,"<>"&"",'Order Summary'!$G$4:$G$200,"Yes") -> 40.6
Q24: ASC 0096 GLOSSY BLACK | R24: =SUMIFS('Order Details'!$Q:$Q,'Order Details'!$N:$N,Dashboard!$Q24,'Order Details'!$E:$E,"Yes",'Order Details'!$C:$C,'Master Data'!$C$4)+SUMIFS('Order Details'!$Q:$Q,'Order Details'!$N:$N,Dashboard!$Q24,'Order Details'!$E:$E,"Yes",'Order Details'!$C:$C,'Master Data'!$C$5)+SUMIFS('Order Details'!$Q:$Q,'Order Details'!$N:$N,Dashboard!$Q24,'Order Details'!$E:$E,"Yes",'Order Details'!$C:$C,'Master Data'!$C$6)+SUMIFS('Order Details'!$Q:$Q,'Order Details'!$N:$N,Dashboard!$Q24,'Order Details'!$E:$E,"Yes",'Order Details'!$C:$C,'Master Data'!$C$7) -> 36500 | S24: =SUMIFS('Order Details'!$O:$O,'Order Details'!$N:$N,Dashboard!$Q24,'Order Details'!$E:$E,"Yes",'Order Details'!$C:$C,'Master Data'!$C$4)+SUMIFS('Order Details'!$O:$O,'Order Details'!$N:$N,Dashboard!$Q24,'Order Details'!$E:$E,"Yes",'Order Details'!$C:$C,'Master Data'!$C$5)+SUMIFS('Order Details'!$O:$O,'Order Details'!$N:$N,Dashboard!$Q24,'Order Details'!$E:$E,"Yes",'Order Details'!$C:$C,'Master Data'!$C$6)+SUMIFS('Order Details'!$O:$O,'Order Details'!$N:$N,Dashboard!$Q24,'Order Details'!$E:$E,"Yes",'Order Details'!$C:$C,'Master Data'!$C$7) -> 1252.426 | T24: =SUMIFS('Order Details'!$P:$P,'Order Details'!$N:$N,Dashboard!$Q24,'Order Details'!$E:$E,"Yes",'Order Details'!$C:$C,'Master Data'!$C$4)+SUMIFS('Order Details'!$P:$P,'Order Details'!$N:$N,Dashboard!$Q24,'Order Details'!$E:$E,"Yes",'Order Details'!$C:$C,'Master Data'!$C$5)+SUMIFS('Order Details'!$P:$P,'Order Details'!$N:$N,Dashboard!$Q24,'Order Details'!$E:$E,"Yes",'Order Details'!$C:$C,'Master Data'!$C$6)+SUMIFS('Order Details'!$P:$P,'Order Details'!$N:$N,Dashboard!$Q24,'Order Details'!$E:$E,"Yes",'Order Details'!$C:$C,'Master Data'!$C$7) -> 116462.16 | U24: =SUMIFS('Order Details'!$V:$V,'Order Details'!$N:$N,Dashboard!$Q24,'Order Details'!$E:$E,"Yes",'Order Details'!$C:$C,'Master Data'!$C$4)+SUMIFS('Order Details'!$V:$V,'Order Details'!$N:$N,Dashboard!$Q24,'Order Details'!$E:$E,"Yes",'Order Details'!$C:$C,'Master Data'!$C$5)+SUMIFS('Order Details'!$V:$V,'Order Details'!$N:$N,Dashboard!$Q24,'Order Details'!$E:$E,"Yes",'Order Details'!$C:$C,'Master Data'!$C$6)+SUMIFS('Order Details'!$V:$V,'Order Details'!$N:$N,Dashboard!$Q24,'Order Details'!$E:$E,"Yes",'Order Details'!$C:$C,'Master Data'!$C$7) -> 898551.29 | AB24: Pending Telex / Seaway: | AC24: =COUNTIFS('Order Summary'!$AJ4:$AJ200,"<>"&"",'Order Summary'!$AM4:$AM200,"",'Order Summary'!$G$4:$G$200,"Yes")+COUNTIFS('Order Summary'!$AJ4:$AJ200,"<>"&"",'Order Summary'!$AM4:$AM200,"PENDING",'Order Summary'!$G$4:$G$200,"Yes") -> 33
Q25: ASC 0069 GLOSSY WHITE | R25: =SUMIFS('Order Details'!$Q:$Q,'Order Details'!$N:$N,Dashboard!$Q25,'Order Details'!$E:$E,"Yes",'Order Details'!$C:$C,'Master Data'!$C$4)+SUMIFS('Order Details'!$Q:$Q,'Order Details'!$N:$N,Dashboard!$Q25,'Order Details'!$E:$E,"Yes",'Order Details'!$C:$C,'Master Data'!$C$5)+SUMIFS('Order Details'!$Q:$Q,'Order Details'!$N:$N,Dashboard!$Q25,'Order Details'!$E:$E,"Yes",'Order Details'!$C:$C,'Master Data'!$C$6)+SUMIFS('Order Details'!$Q:$Q,'Order Details'!$N:$N,Dashboard!$Q25,'Order Details'!$E:$E,"Yes",'Order Details'!$C:$C,'Master Data'!$C$7) -> 66100 | S25: =SUMIFS('Order Details'!$O:$O,'Order Details'!$N:$N,Dashboard!$Q25,'Order Details'!$E:$E,"Yes",'Order Details'!$C:$C,'Master Data'!$C$4)+SUMIFS('Order Details'!$O:$O,'Order Details'!$N:$N,Dashboard!$Q25,'Order Details'!$E:$E,"Yes",'Order Details'!$C:$C,'Master Data'!$C$5)+SUMIFS('Order Details'!$O:$O,'Order Details'!$N:$N,Dashboard!$Q25,'Order Details'!$E:$E,"Yes",'Order Details'!$C:$C,'Master Data'!$C$6)+SUMIFS('Order Details'!$O:$O,'Order Details'!$N:$N,Dashboard!$Q25,'Order Details'!$E:$E,"Yes",'Order Details'!$C:$C,'Master Data'!$C$7) -> 2234.434 | T25: =SUMIFS('Order Details'!$P:$P,'Order Details'!$N:$N,Dashboard!$Q25,'Order Details'!$E:$E,"Yes",'Order Details'!$C:$C,'Master Data'!$C$4)+SUMIFS('Order Details'!$P:$P,'Order Details'!$N:$N,Dashboard!$Q25,'Order Details'!$E:$E,"Yes",'Order Details'!$C:$C,'Master Data'!$C$5)+SUMIFS('Order Details'!$P:$P,'Order Details'!$N:$N,Dashboard!$Q25,'Order Details'!$E:$E,"Yes",'Order Details'!$C:$C,'Master Data'!$C$6)+SUMIFS('Order Details'!$P:$P,'Order Details'!$N:$N,Dashboard!$Q25,'Order Details'!$E:$E,"Yes",'Order Details'!$C:$C,'Master Data'!$C$7) -> 207781.16 | U25: =SUMIFS('Order Details'!$V:$V,'Order Details'!$N:$N,Dashboard!$Q25,'Order Details'!$E:$E,"Yes",'Order Details'!$C:$C,'Master Data'!$C$4)+SUMIFS('Order Details'!$V:$V,'Order Details'!$N:$N,Dashboard!$Q25,'Order Details'!$E:$E,"Yes",'Order Details'!$C:$C,'Master Data'!$C$5)+SUMIFS('Order Details'!$V:$V,'Order Details'!$N:$N,Dashboard!$Q25,'Order Details'!$E:$E,"Yes",'Order Details'!$C:$C,'Master Data'!$C$6)+SUMIFS('Order Details'!$V:$V,'Order Details'!$N:$N,Dashboard!$Q25,'Order Details'!$E:$E,"Yes",'Order Details'!$C:$C,'Master Data'!$C$7) -> 1604447.2
Q26: AMC 0103 SILVER FROST | R26: =SUMIFS('Order Details'!$Q:$Q,'Order Details'!$N:$N,Dashboard!$Q26,'Order Details'!$E:$E,"Yes",'Order Details'!$C:$C,'Master Data'!$C$4)+SUMIFS('Order Details'!$Q:$Q,'Order Details'!$N:$N,Dashboard!$Q26,'Order Details'!$E:$E,"Yes",'Order Details'!$C:$C,'Master Data'!$C$5)+SUMIFS('Order Details'!$Q:$Q,'Order Details'!$N:$N,Dashboard!$Q26,'Order Details'!$E:$E,"Yes",'Order Details'!$C:$C,'Master Data'!$C$6)+SUMIFS('Order Details'!$Q:$Q,'Order Details'!$N:$N,Dashboard!$Q26,'Order Details'!$E:$E,"Yes",'Order Details'!$C:$C,'Master Data'!$C$7) -> 25200 | S26: =SUMIFS('Order Details'!$O:$O,'Order Details'!$N:$N,Dashboard!$Q26,'Order Details'!$E:$E,"Yes",'Order Details'!$C:$C,'Master Data'!$C$4)+SUMIFS('Order Details'!$O:$O,'Order Details'!$N:$N,Dashboard!$Q26,'Order Details'!$E:$E,"Yes",'Order Details'!$C:$C,'Master Data'!$C$5)+SUMIFS('Order Details'!$O:$O,'Order Details'!$N:$N,Dashboard!$Q26,'Order Details'!$E:$E,"Yes",'Order Details'!$C:$C,'Master Data'!$C$6)+SUMIFS('Order Details'!$O:$O,'Order Details'!$N:$N,Dashboard!$Q26,'Order Details'!$E:$E,"Yes",'Order Details'!$C:$C,'Master Data'!$C$7) -> 857.805 | T26: =SUMIFS('Order Details'!$P:$P,'Order Details'!$N:$N,Dashboard!$Q26,'Order Details'!$E:$E,"Yes",'Order Details'!$C:$C,'Master Data'!$C$4)+SUMIFS('Order Details'!$P:$P,'Order Details'!$N:$N,Dashboard!$Q26,'Order Details'!$E:$E,"Yes",'Order Details'!$C:$C,'Master Data'!$C$5)+SUMIFS('Order Details'!$P:$P,'Order Details'!$N:$N,Dashboard!$Q26,'Order Details'!$E:$E,"Yes",'Order Details'!$C:$C,'Master Data'!$C$6)+SUMIFS('Order Details'!$P:$P,'Order Details'!$N:$N,Dashboard!$Q26,'Order Details'!$E:$E,"Yes",'Order Details'!$C:$C,'Master Data'!$C$7) -> 79768.146 | U26: =SUMIFS('Order Details'!$V:$V,'Order Details'!$N:$N,Dashboard!$Q26,'Order Details'!$E:$E,"Yes",'Order Details'!$C:$C,'Master Data'!$C$4)+SUMIFS('Order Details'!$V:$V,'Order Details'!$N:$N,Dashboard!$Q26,'Order Details'!$E:$E,"Yes",'Order Details'!$C:$C,'Master Data'!$C$5)+SUMIFS('Order Details'!$V:$V,'Order Details'!$N:$N,Dashboard!$Q26,'Order Details'!$E:$E,"Yes",'Order Details'!$C:$C,'Master Data'!$C$6)+SUMIFS('Order Details'!$V:$V,'Order Details'!$N:$N,Dashboard!$Q26,'Order Details'!$E:$E,"Yes",'Order Details'!$C:$C,'Master Data'!$C$7) -> 616120.48
Q27: AMC 0086 CHARCOAL METALLIC | R27: =SUMIFS('Order Details'!$Q:$Q,'Order Details'!$N:$N,Dashboard!$Q27,'Order Details'!$E:$E,"Yes",'Order Details'!$C:$C,'Master Data'!$C$4)+SUMIFS('Order Details'!$Q:$Q,'Order Details'!$N:$N,Dashboard!$Q27,'Order Details'!$E:$E,"Yes",'Order Details'!$C:$C,'Master Data'!$C$5)+SUMIFS('Order Details'!$Q:$Q,'Order Details'!$N:$N,Dashboard!$Q27,'Order Details'!$E:$E,"Yes",'Order Details'!$C:$C,'Master Data'!$C$6)+SUMIFS('Order Details'!$Q:$Q,'Order Details'!$N:$N,Dashboard!$Q27,'Order Details'!$E:$E,"Yes",'Order Details'!$C:$C,'Master Data'!$C$7) -> 15750 | S27: =SUMIFS('Order Details'!$O:$O,'Order Details'!$N:$N,Dashboard!$Q27,'Order Details'!$E:$E,"Yes",'Order Details'!$C:$C,'Master Data'!$C$4)+SUMIFS('Order Details'!$O:$O,'Order Details'!$N:$N,Dashboard!$Q27,'Order Details'!$E:$E,"Yes",'Order Details'!$C:$C,'Master Data'!$C$5)+SUMIFS('Order Details'!$O:$O,'Order Details'!$N:$N,Dashboard!$Q27,'Order Details'!$E:$E,"Yes",'Order Details'!$C:$C,'Master Data'!$C$6)+SUMIFS('Order Details'!$O:$O,'Order Details'!$N:$N,Dashboard!$Q27,'Order Details'!$E:$E,"Yes",'Order Details'!$C:$C,'Master Data'!$C$7) -> 541.586 | T27: =SUMIFS('Order Details'!$P:$P,'Order Details'!$N:$N,Dashboard!$Q27,'Order Details'!$E:$E,"Yes",'Order Details'!$C:$C,'Master Data'!$C$4)+SUMIFS('Order Details'!$P:$P,'Order Details'!$N:$N,Dashboard!$Q27,'Order Details'!$E:$E,"Yes",'Order Details'!$C:$C,'Master Data'!$C$5)+SUMIFS('Order Details'!$P:$P,'Order Details'!$N:$N,Dashboard!$Q27,'Order Details'!$E:$E,"Yes",'Order Details'!$C:$C,'Master Data'!$C$6)+SUMIFS('Order Details'!$P:$P,'Order Details'!$N:$N,Dashboard!$Q27,'Order Details'!$E:$E,"Yes",'Order Details'!$C:$C,'Master Data'!$C$7) -> 50362.18 | U27: =SUMIFS('Order Details'!$V:$V,'Order Details'!$N:$N,Dashboard!$Q27,'Order Details'!$E:$E,"Yes",'Order Details'!$C:$C,'Master Data'!$C$4)+SUMIFS('Order Details'!$V:$V,'Order Details'!$N:$N,Dashboard!$Q27,'Order Details'!$E:$E,"Yes",'Order Details'!$C:$C,'Master Data'!$C$5)+SUMIFS('Order Details'!$V:$V,'Order Details'!$N:$N,Dashboard!$Q27,'Order Details'!$E:$E,"Yes",'Order Details'!$C:$C,'Master Data'!$C$6)+SUMIFS('Order Details'!$V:$V,'Order Details'!$N:$N,Dashboard!$Q27,'Order Details'!$E:$E,"Yes",'Order Details'!$C:$C,'Master Data'!$C$7) -> 416252.2
Q28: ASC 0099 MATTE BLACK | R28: =SUMIFS('Order Details'!$Q:$Q,'Order Details'!$N:$N,Dashboard!$Q28,'Order Details'!$E:$E,"Yes",'Order Details'!$C:$C,'Master Data'!$C$4)+SUMIFS('Order Details'!$Q:$Q,'Order Details'!$N:$N,Dashboard!$Q28,'Order Details'!$E:$E,"Yes",'Order Details'!$C:$C,'Master Data'!$C$5)+SUMIFS('Order Details'!$Q:$Q,'Order Details'!$N:$N,Dashboard!$Q28,'Order Details'!$E:$E,"Yes",'Order Details'!$C:$C,'Master Data'!$C$6)+SUMIFS('Order Details'!$Q:$Q,'Order Details'!$N:$N,Dashboard!$Q28,'Order Details'!$E:$E,"Yes",'Order Details'!$C:$C,'Master Data'!$C$7) -> 0 | S28: =SUMIFS('Order Details'!$O:$O,'Order Details'!$N:$N,Dashboard!$Q28,'Order Details'!$E:$E,"Yes",'Order Details'!$C:$C,'Master Data'!$C$4)+SUMIFS('Order Details'!$O:$O,'Order Details'!$N:$N,Dashboard!$Q28,'Order Details'!$E:$E,"Yes",'Order Details'!$C:$C,'Master Data'!$C$5)+SUMIFS('Order Details'!$O:$O,'Order Details'!$N:$N,Dashboard!$Q28,'Order Details'!$E:$E,"Yes",'Order Details'!$C:$C,'Master Data'!$C$6)+SUMIFS('Order Details'!$O:$O,'Order Details'!$N:$N,Dashboard!$Q28,'Order Details'!$E:$E,"Yes",'Order Details'!$C:$C,'Master Data'!$C$7) -> 0 | T28: =SUMIFS('Order Details'!$P:$P,'Order Details'!$N:$N,Dashboard!$Q28,'Order Details'!$E:$E,"Yes",'Order Details'!$C:$C,'Master Data'!$C$4)+SUMIFS('Order Details'!$P:$P,'Order Details'!$N:$N,Dashboard!$Q28,'Order Details'!$E:$E,"Yes",'Order Details'!$C:$C,'Master Data'!$C$5)+SUMIFS('Order Details'!$P:$P,'Order Details'!$N:$N,Dashboard!$Q28,'Order Details'!$E:$E,"Yes",'Order Details'!$C:$C,'Master Data'!$C$6)+SUMIFS('Order Details'!$P:$P,'Order Details'!$N:$N,Dashboard!$Q28,'Order Details'!$E:$E,"Yes",'Order Details'!$C:$C,'Master Data'!$C$7) -> 0 | U28: =SUMIFS('Order Details'!$V:$V,'Order Details'!$N:$N,Dashboard!$Q28,'Order Details'!$E:$E,"Yes",'Order Details'!$C:$C,'Master Data'!$C$4)+SUMIFS('Order Details'!$V:$V,'Order Details'!$N:$N,Dashboard!$Q28,'Order Details'!$E:$E,"Yes",'Order Details'!$C:$C,'Master Data'!$C$5)+SUMIFS('Order Details'!$V:$V,'Order Details'!$N:$N,Dashboard!$Q28,'Order Details'!$E:$E,"Yes",'Order Details'!$C:$C,'Master Data'!$C$6)+SUMIFS('Order Details'!$V:$V,'Order Details'!$N:$N,Dashboard!$Q28,'Order Details'!$E:$E,"Yes",'Order Details'!$C:$C,'Master Data'!$C$7) -> 0
Q29: ASC 0092 PEPSI BLUE | R29: =SUMIFS('Order Details'!$Q:$Q,'Order Details'!$N:$N,Dashboard!$Q29,'Order Details'!$E:$E,"Yes",'Order Details'!$C:$C,'Master Data'!$C$4)+SUMIFS('Order Details'!$Q:$Q,'Order Details'!$N:$N,Dashboard!$Q29,'Order Details'!$E:$E,"Yes",'Order Details'!$C:$C,'Master Data'!$C$5)+SUMIFS('Order Details'!$Q:$Q,'Order Details'!$N:$N,Dashboard!$Q29,'Order Details'!$E:$E,"Yes",'Order Details'!$C:$C,'Master Data'!$C$6)+SUMIFS('Order Details'!$Q:$Q,'Order Details'!$N:$N,Dashboard!$Q29,'Order Details'!$E:$E,"Yes",'Order Details'!$C:$C,'Master Data'!$C$7) -> 200 | S29: =SUMIFS('Order Details'!$O:$O,'Order Details'!$N:$N,Dashboard!$Q29,'Order Details'!$E:$E,"Yes",'Order Details'!$C:$C,'Master Data'!$C$4)+SUMIFS('Order Details'!$O:$O,'Order Details'!$N:$N,Dashboard!$Q29,'Order Details'!$E:$E,"Yes",'Order Details'!$C:$C,'Master Data'!$C$5)+SUMIFS('Order Details'!$O:$O,'Order Details'!$N:$N,Dashboard!$Q29,'Order Details'!$E:$E,"Yes",'Order Details'!$C:$C,'Master Data'!$C$6)+SUMIFS('Order Details'!$O:$O,'Order Details'!$N:$N,Dashboard!$Q29,'Order Details'!$E:$E,"Yes",'Order Details'!$C:$C,'Master Data'!$C$7) -> 8.167 | T29: =SUMIFS('Order Details'!$P:$P,'Order Details'!$N:$N,Dashboard!$Q29,'Order Details'!$E:$E,"Yes",'Order Details'!$C:$C,'Master Data'!$C$4)+SUMIFS('Order Details'!$P:$P,'Order Details'!$N:$N,Dashboard!$Q29,'Order Details'!$E:$E,"Yes",'Order Details'!$C:$C,'Master Data'!$C$5)+SUMIFS('Order Details'!$P:$P,'Order Details'!$N:$N,Dashboard!$Q29,'Order Details'!$E:$E,"Yes",'Order Details'!$C:$C,'Master Data'!$C$6)+SUMIFS('Order Details'!$P:$P,'Order Details'!$N:$N,Dashboard!$Q29,'Order Details'!$E:$E,"Yes",'Order Details'!$C:$C,'Master Data'!$C$7) -> 759.45 | U29: =SUMIFS('Order Details'!$V:$V,'Order Details'!$N:$N,Dashboard!$Q29,'Order Details'!$E:$E,"Yes",'Order Details'!$C:$C,'Master Data'!$C$4)+SUMIFS('Order Details'!$V:$V,'Order Details'!$N:$N,Dashboard!$Q29,'Order Details'!$E:$E,"Yes",'Order Details'!$C:$C,'Master Data'!$C$5)+SUMIFS('Order Details'!$V:$V,'Order Details'!$N:$N,Dashboard!$Q29,'Order Details'!$E:$E,"Yes",'Order Details'!$C:$C,'Master Data'!$C$6)+SUMIFS('Order Details'!$V:$V,'Order Details'!$N:$N,Dashboard!$Q29,'Order Details'!$E:$E,"Yes",'Order Details'!$C:$C,'Master Data'!$C$7) -> 5870.5485
Q30: ASC 0089 VICTORY RED | R30: =SUMIFS('Order Details'!$Q:$Q,'Order Details'!$N:$N,Dashboard!$Q30,'Order Details'!$E:$E,"Yes",'Order Details'!$C:$C,'Master Data'!$C$4)+SUMIFS('Order Details'!$Q:$Q,'Order Details'!$N:$N,Dashboard!$Q30,'Order Details'!$E:$E,"Yes",'Order Details'!$C:$C,'Master Data'!$C$5)+SUMIFS('Order Details'!$Q:$Q,'Order Details'!$N:$N,Dashboard!$Q30,'Order Details'!$E:$E,"Yes",'Order Details'!$C:$C,'Master Data'!$C$6)+SUMIFS('Order Details'!$Q:$Q,'Order Details'!$N:$N,Dashboard!$Q30,'Order Details'!$E:$E,"Yes",'Order Details'!$C:$C,'Master Data'!$C$7) -> 8400 | S30: =SUMIFS('Order Details'!$O:$O,'Order Details'!$N:$N,Dashboard!$Q30,'Order Details'!$E:$E,"Yes",'Order Details'!$C:$C,'Master Data'!$C$4)+SUMIFS('Order Details'!$O:$O,'Order Details'!$N:$N,Dashboard!$Q30,'Order Details'!$E:$E,"Yes",'Order Details'!$C:$C,'Master Data'!$C$5)+SUMIFS('Order Details'!$O:$O,'Order Details'!$N:$N,Dashboard!$Q30,'Order Details'!$E:$E,"Yes",'Order Details'!$C:$C,'Master Data'!$C$6)+SUMIFS('Order Details'!$O:$O,'Order Details'!$N:$N,Dashboard!$Q30,'Order Details'!$E:$E,"Yes",'Order Details'!$C:$C,'Master Data'!$C$7) -> 291.685 | T30: =SUMIFS('Order Details'!$P:$P,'Order Details'!$N:$N,Dashboard!$Q30,'Order Details'!$E:$E,"Yes",'Order Details'!$C:$C,'Master Data'!$C$4)+SUMIFS('Order Details'!$P:$P,'Order Details'!$N:$N,Dashboard!$Q30,'Order Details'!$E:$E,"Yes",'Order Details'!$C:$C,'Master Data'!$C$5)+SUMIFS('Order Details'!$P:$P,'Order Details'!$N:$N,Dashboard!$Q30,'Order Details'!$E:$E,"Yes",'Order Details'!$C:$C,'Master Data'!$C$6)+SUMIFS('Order Details'!$P:$P,'Order Details'!$N:$N,Dashboard!$Q30,'Order Details'!$E:$E,"Yes",'Order Details'!$C:$C,'Master Data'!$C$7) -> 27124.317 | U30: =SUMIFS('Order Details'!$V:$V,'Order Details'!$N:$N,Dashboard!$Q30,'Order Details'!$E:$E,"Yes",'Order Details'!$C:$C,'Master Data'!$C$4)+SUMIFS('Order Details'!$V:$V,'Order Details'!$N:$N,Dashboard!$Q30,'Order Details'!$E:$E,"Yes",'Order Details'!$C:$C,'Master Data'!$C$5)+SUMIFS('Order Details'!$V:$V,'Order Details'!$N:$N,Dashboard!$Q30,'Order Details'!$E:$E,"Yes",'Order Details'!$C:$C,'Master Data'!$C$6)+SUMIFS('Order Details'!$V:$V,'Order Details'!$N:$N,Dashboard!$Q30,'Order Details'!$E:$E,"Yes",'Order Details'!$C:$C,'Master Data'!$C$7) -> 207377.53
Q31: AMC 0104 PEWTER | R31: =SUMIFS('Order Details'!$Q:$Q,'Order Details'!$N:$N,Dashboard!$Q31,'Order Details'!$E:$E,"Yes",'Order Details'!$C:$C,'Master Data'!$C$4)+SUMIFS('Order Details'!$Q:$Q,'Order Details'!$N:$N,Dashboard!$Q31,'Order Details'!$E:$E,"Yes",'Order Details'!$C:$C,'Master Data'!$C$5)+SUMIFS('Order Details'!$Q:$Q,'Order Details'!$N:$N,Dashboard!$Q31,'Order Details'!$E:$E,"Yes",'Order Details'!$C:$C,'Master Data'!$C$6)+SUMIFS('Order Details'!$Q:$Q,'Order Details'!$N:$N,Dashboard!$Q31,'Order Details'!$E:$E,"Yes",'Order Details'!$C:$C,'Master Data'!$C$7) -> 0 | S31: =SUMIFS('Order Details'!$O:$O,'Order Details'!$N:$N,Dashboard!$Q31,'Order Details'!$E:$E,"Yes",'Order Details'!$C:$C,'Master Data'!$C$4)+SUMIFS('Order Details'!$O:$O,'Order Details'!$N:$N,Dashboard!$Q31,'Order Details'!$E:$E,"Yes",'Order Details'!$C:$C,'Master Data'!$C$5)+SUMIFS('Order Details'!$O:$O,'Order Details'!$N:$N,Dashboard!$Q31,'Order Details'!$E:$E,"Yes",'Order Details'!$C:$C,'Master Data'!$C$6)+SUMIFS('Order Details'!$O:$O,'Order Details'!$N:$N,Dashboard!$Q31,'Order Details'!$E:$E,"Yes",'Order Details'!$C:$C,'Master Data'!$C$7) -> 0 | T31: =SUMIFS('Order Details'!$P:$P,'Order Details'!$N:$N,Dashboard!$Q31,'Order Details'!$E:$E,"Yes",'Order Details'!$C:$C,'Master Data'!$C$4)+SUMIFS('Order Details'!$P:$P,'Order Details'!$N:$N,Dashboard!$Q31,'Order Details'!$E:$E,"Yes",'Order Details'!$C:$C,'Master Data'!$C$5)+SUMIFS('Order Details'!$P:$P,'Order Details'!$N:$N,Dashboard!$Q31,'Order Details'!$E:$E,"Yes",'Order Details'!$C:$C,'Master Data'!$C$6)+SUMIFS('Order Details'!$P:$P,'Order Details'!$N:$N,Dashboard!$Q31,'Order Details'!$E:$E,"Yes",'Order Details'!$C:$C,'Master Data'!$C$7) -> 0 | U31: =SUMIFS('Order Details'!$V:$V,'Order Details'!$N:$N,Dashboard!$Q31,'Order Details'!$E:$E,"Yes",'Order Details'!$C:$C,'Master Data'!$C$4)+SUMIFS('Order Details'!$V:$V,'Order Details'!$N:$N,Dashboard!$Q31,'Order Details'!$E:$E,"Yes",'Order Details'!$C:$C,'Master Data'!$C$5)+SUMIFS('Order Details'!$V:$V,'Order Details'!$N:$N,Dashboard!$Q31,'Order Details'!$E:$E,"Yes",'Order Details'!$C:$C,'Master Data'!$C$6)+SUMIFS('Order Details'!$V:$V,'Order Details'!$N:$N,Dashboard!$Q31,'Order Details'!$E:$E,"Yes",'Order Details'!$C:$C,'Master Data'!$C$7) -> 0
Q32: ASC 0105 INDIGO BLUE | R32: =SUMIFS('Order Details'!$Q:$Q,'Order Details'!$N:$N,Dashboard!$Q32,'Order Details'!$E:$E,"Yes",'Order Details'!$C:$C,'Master Data'!$C$4)+SUMIFS('Order Details'!$Q:$Q,'Order Details'!$N:$N,Dashboard!$Q32,'Order Details'!$E:$E,"Yes",'Order Details'!$C:$C,'Master Data'!$C$5)+SUMIFS('Order Details'!$Q:$Q,'Order Details'!$N:$N,Dashboard!$Q32,'Order Details'!$E:$E,"Yes",'Order Details'!$C:$C,'Master Data'!$C$6)+SUMIFS('Order Details'!$Q:$Q,'Order Details'!$N:$N,Dashboard!$Q32,'Order Details'!$E:$E,"Yes",'Order Details'!$C:$C,'Master Data'!$C$7) -> 7750 | S32: =SUMIFS('Order Details'!$O:$O,'Order Details'!$N:$N,Dashboard!$Q32,'Order Details'!$E:$E,"Yes",'Order Details'!$C:$C,'Master Data'!$C$4)+SUMIFS('Order Details'!$O:$O,'Order Details'!$N:$N,Dashboard!$Q32,'Order Details'!$E:$E,"Yes",'Order Details'!$C:$C,'Master Data'!$C$5)+SUMIFS('Order Details'!$O:$O,'Order Details'!$N:$N,Dashboard!$Q32,'Order Details'!$E:$E,"Yes",'Order Details'!$C:$C,'Master Data'!$C$6)+SUMIFS('Order Details'!$O:$O,'Order Details'!$N:$N,Dashboard!$Q32,'Order Details'!$E:$E,"Yes",'Order Details'!$C:$C,'Master Data'!$C$7) -> 266.981 | T32: =SUMIFS('Order Details'!$P:$P,'Order Details'!$N:$N,Dashboard!$Q32,'Order Details'!$E:$E,"Yes",'Order Details'!$C:$C,'Master Data'!$C$4)+SUMIFS('Order Details'!$P:$P,'Order Details'!$N:$N,Dashboard!$Q32,'Order Details'!$E:$E,"Yes",'Order Details'!$C:$C,'Master Data'!$C$5)+SUMIFS('Order Details'!$P:$P,'Order Details'!$N:$N,Dashboard!$Q32,'Order Details'!$E:$E,"Yes",'Order Details'!$C:$C,'Master Data'!$C$6)+SUMIFS('Order Details'!$P:$P,'Order Details'!$N:$N,Dashboard!$Q32,'Order Details'!$E:$E,"Yes",'Order Details'!$C:$C,'Master Data'!$C$7) -> 24826.981 | U32: =SUMIFS('Order Details'!$V:$V,'Order Details'!$N:$N,Dashboard!$Q32,'Order Details'!$E:$E,"Yes",'Order Details'!$C:$C,'Master Data'!$C$4)+SUMIFS('Order Details'!$V:$V,'Order Details'!$N:$N,Dashboard!$Q32,'Order Details'!$E:$E,"Yes",'Order Details'!$C:$C,'Master Data'!$C$5)+SUMIFS('Order Details'!$V:$V,'Order Details'!$N:$N,Dashboard!$Q32,'Order Details'!$E:$E,"Yes",'Order Details'!$C:$C,'Master Data'!$C$6)+SUMIFS('Order Details'!$V:$V,'Order Details'!$N:$N,Dashboard!$Q32,'Order Details'!$E:$E,"Yes",'Order Details'!$C:$C,'Master Data'!$C$7) -> 203450.98
Q33: ASC 0164 ARMY GREEN | R33: =SUMIFS('Order Details'!$Q:$Q,'Order Details'!$N:$N,Dashboard!$Q33,'Order Details'!$E:$E,"Yes",'Order Details'!$C:$C,'Master Data'!$C$4)+SUMIFS('Order Details'!$Q:$Q,'Order Details'!$N:$N,Dashboard!$Q33,'Order Details'!$E:$E,"Yes",'Order Details'!$C:$C,'Master Data'!$C$5)+SUMIFS('Order Details'!$Q:$Q,'Order Details'!$N:$N,Dashboard!$Q33,'Order Details'!$E:$E,"Yes",'Order Details'!$C:$C,'Master Data'!$C$6)+SUMIFS('Order Details'!$Q:$Q,'Order Details'!$N:$N,Dashboard!$Q33,'Order Details'!$E:$E,"Yes",'Order Details'!$C:$C,'Master Data'!$C$7) -> 2800 | S33: =SUMIFS('Order Details'!$O:$O,'Order Details'!$N:$N,Dashboard!$Q33,'Order Details'!$E:$E,"Yes",'Order Details'!$C:$C,'Master Data'!$C$4)+SUMIFS('Order Details'!$O:$O,'Order Details'!$N:$N,Dashboard!$Q33,'Order Details'!$E:$E,"Yes",'Order Details'!$C:$C,'Master Data'!$C$5)+SUMIFS('Order Details'!$O:$O,'Order Details'!$N:$N,Dashboard!$Q33,'Order Details'!$E:$E,"Yes",'Order Details'!$C:$C,'Master Data'!$C$6)+SUMIFS('Order Details'!$O:$O,'Order Details'!$N:$N,Dashboard!$Q33,'Order Details'!$E:$E,"Yes",'Order Details'!$C:$C,'Master Data'!$C$7) -> 93.61 | T33: =SUMIFS('Order Details'!$P:$P,'Order Details'!$N:$N,Dashboard!$Q33,'Order Details'!$E:$E,"Yes",'Order Details'!$C:$C,'Master Data'!$C$4)+SUMIFS('Order Details'!$P:$P,'Order Details'!$N:$N,Dashboard!$Q33,'Order Details'!$E:$E,"Yes",'Order Details'!$C:$C,'Master Data'!$C$5)+SUMIFS('Order Details'!$P:$P,'Order Details'!$N:$N,Dashboard!$Q33,'Order Details'!$E:$E,"Yes",'Order Details'!$C:$C,'Master Data'!$C$6)+SUMIFS('Order Details'!$P:$P,'Order Details'!$N:$N,Dashboard!$Q33,'Order Details'!$E:$E,"Yes",'Order Details'!$C:$C,'Master Data'!$C$7) -> 8705.04 | U33: =SUMIFS('Order Details'!$V:$V,'Order Details'!$N:$N,Dashboard!$Q33,'Order Details'!$E:$E,"Yes",'Order Details'!$C:$C,'Master Data'!$C$4)+SUMIFS('Order Details'!$V:$V,'Order Details'!$N:$N,Dashboard!$Q33,'Order Details'!$E:$E,"Yes",'Order Details'!$C:$C,'Master Data'!$C$5)+SUMIFS('Order Details'!$V:$V,'Order Details'!$N:$N,Dashboard!$Q33,'Order Details'!$E:$E,"Yes",'Order Details'!$C:$C,'Master Data'!$C$6)+SUMIFS('Order Details'!$V:$V,'Order Details'!$N:$N,Dashboard!$Q33,'Order Details'!$E:$E,"Yes",'Order Details'!$C:$C,'Master Data'!$C$7) -> 71990.681
Q34: ASC 0127 SAND SAHARA | R34: =SUMIFS('Order Details'!$Q:$Q,'Order Details'!$N:$N,Dashboard!$Q34,'Order Details'!$E:$E,"Yes",'Order Details'!$C:$C,'Master Data'!$C$4)+SUMIFS('Order Details'!$Q:$Q,'Order Details'!$N:$N,Dashboard!$Q34,'Order Details'!$E:$E,"Yes",'Order Details'!$C:$C,'Master Data'!$C$5)+SUMIFS('Order Details'!$Q:$Q,'Order Details'!$N:$N,Dashboard!$Q34,'Order Details'!$E:$E,"Yes",'Order Details'!$C:$C,'Master Data'!$C$6)+SUMIFS('Order Details'!$Q:$Q,'Order Details'!$N:$N,Dashboard!$Q34,'Order Details'!$E:$E,"Yes",'Order Details'!$C:$C,'Master Data'!$C$7) -> 0 | S34: =SUMIFS('Order Details'!$O:$O,'Order Details'!$N:$N,Dashboard!$Q34,'Order Details'!$E:$E,"Yes",'Order Details'!$C:$C,'Master Data'!$C$4)+SUMIFS('Order Details'!$O:$O,'Order Details'!$N:$N,Dashboard!$Q34,'Order Details'!$E:$E,"Yes",'Order Details'!$C:$C,'Master Data'!$C$5)+SUMIFS('Order Details'!$O:$O,'Order Details'!$N:$N,Dashboard!$Q34,'Order Details'!$E:$E,"Yes",'Order Details'!$C:$C,'Master Data'!$C$6)+SUMIFS('Order Details'!$O:$O,'Order Details'!$N:$N,Dashboard!$Q34,'Order Details'!$E:$E,"Yes",'Order Details'!$C:$C,'Master Data'!$C$7) -> 0 | T34: =SUMIFS('Order Details'!$P:$P,'Order Details'!$N:$N,Dashboard!$Q34,'Order Details'!$E:$E,"Yes",'Order Details'!$C:$C,'Master Data'!$C$4)+SUMIFS('Order Details'!$P:$P,'Order Details'!$N:$N,Dashboard!$Q34,'Order Details'!$E:$E,"Yes",'Order Details'!$C:$C,'Master Data'!$C$5)+SUMIFS('Order Details'!$P:$P,'Order Details'!$N:$N,Dashboard!$Q34,'Order Details'!$E:$E,"Yes",'Order Details'!$C:$C,'Master Data'!$C$6)+SUMIFS('Order Details'!$P:$P,'Order Details'!$N:$N,Dashboard!$Q34,'Order Details'!$E:$E,"Yes",'Order Details'!$C:$C,'Master Data'!$C$7) -> 0 | U34: =SUMIFS('Order Details'!$V:$V,'Order Details'!$N:$N,Dashboard!$Q34,'Order Details'!$E:$E,"Yes",'Order Details'!$C:$C,'Master Data'!$C$4)+SUMIFS('Order Details'!$V:$V,'Order Details'!$N:$N,Dashboard!$Q34,'Order Details'!$E:$E,"Yes",'Order Details'!$C:$C,'Master Data'!$C$5)+SUMIFS('Order Details'!$V:$V,'Order Details'!$N:$N,Dashboard!$Q34,'Order Details'!$E:$E,"Yes",'Order Details'!$C:$C,'Master Data'!$C$6)+SUMIFS('Order Details'!$V:$V,'Order Details'!$N:$N,Dashboard!$Q34,'Order Details'!$E:$E,"Yes",'Order Details'!$C:$C,'Master Data'!$C$7) -> 0
Q35: ASC 0208 SAND SAHARA MATTE | R35: =SUMIFS('Order Details'!$Q:$Q,'Order Details'!$N:$N,Dashboard!$Q35,'Order Details'!$E:$E,"Yes",'Order Details'!$C:$C,'Master Data'!$C$4)+SUMIFS('Order Details'!$Q:$Q,'Order Details'!$N:$N,Dashboard!$Q35,'Order Details'!$E:$E,"Yes",'Order Details'!$C:$C,'Master Data'!$C$5)+SUMIFS('Order Details'!$Q:$Q,'Order Details'!$N:$N,Dashboard!$Q35,'Order Details'!$E:$E,"Yes",'Order Details'!$C:$C,'Master Data'!$C$6)+SUMIFS('Order Details'!$Q:$Q,'Order Details'!$N:$N,Dashboard!$Q35,'Order Details'!$E:$E,"Yes",'Order Details'!$C:$C,'Master Data'!$C$7) -> 2400 | S35: =SUMIFS('Order Details'!$O:$O,'Order Details'!$N:$N,Dashboard!$Q35,'Order Details'!$E:$E,"Yes",'Order Details'!$C:$C,'Master Data'!$C$4)+SUMIFS('Order Details'!$O:$O,'Order Details'!$N:$N,Dashboard!$Q35,'Order Details'!$E:$E,"Yes",'Order Details'!$C:$C,'Master Data'!$C$5)+SUMIFS('Order Details'!$O:$O,'Order Details'!$N:$N,Dashboard!$Q35,'Order Details'!$E:$E,"Yes",'Order Details'!$C:$C,'Master Data'!$C$6)+SUMIFS('Order Details'!$O:$O,'Order Details'!$N:$N,Dashboard!$Q35,'Order Details'!$E:$E,"Yes",'Order Details'!$C:$C,'Master Data'!$C$7) -> 80.169 | T35: =SUMIFS('Order Details'!$P:$P,'Order Details'!$N:$N,Dashboard!$Q35,'Order Details'!$E:$E,"Yes",'Order Details'!$C:$C,'Master Data'!$C$4)+SUMIFS('Order Details'!$P:$P,'Order Details'!$N:$N,Dashboard!$Q35,'Order Details'!$E:$E,"Yes",'Order Details'!$C:$C,'Master Data'!$C$5)+SUMIFS('Order Details'!$P:$P,'Order Details'!$N:$N,Dashboard!$Q35,'Order Details'!$E:$E,"Yes",'Order Details'!$C:$C,'Master Data'!$C$6)+SUMIFS('Order Details'!$P:$P,'Order Details'!$N:$N,Dashboard!$Q35,'Order Details'!$E:$E,"Yes",'Order Details'!$C:$C,'Master Data'!$C$7) -> 7455.06 | U35: =SUMIFS('Order Details'!$V:$V,'Order Details'!$N:$N,Dashboard!$Q35,'Order Details'!$E:$E,"Yes",'Order Details'!$C:$C,'Master Data'!$C$4)+SUMIFS('Order Details'!$V:$V,'Order Details'!$N:$N,Dashboard!$Q35,'Order Details'!$E:$E,"Yes",'Order Details'!$C:$C,'Master Data'!$C$5)+SUMIFS('Order Details'!$V:$V,'Order Details'!$N:$N,Dashboard!$Q35,'Order Details'!$E:$E,"Yes",'Order Details'!$C:$C,'Master Data'!$C$6)+SUMIFS('Order Details'!$V:$V,'Order Details'!$N:$N,Dashboard!$Q35,'Order Details'!$E:$E,"Yes",'Order Details'!$C:$C,'Master Data'!$C$7) -> 61653.346
Q36: ASC 0090 YELLOW | R36: =SUMIFS('Order Details'!$Q:$Q,'Order Details'!$N:$N,Dashboard!$Q36,'Order Details'!$E:$E,"Yes",'Order Details'!$C:$C,'Master Data'!$C$4)+SUMIFS('Order Details'!$Q:$Q,'Order Details'!$N:$N,Dashboard!$Q36,'Order Details'!$E:$E,"Yes",'Order Details'!$C:$C,'Master Data'!$C$5)+SUMIFS('Order Details'!$Q:$Q,'Order Details'!$N:$N,Dashboard!$Q36,'Order Details'!$E:$E,"Yes",'Order Details'!$C:$C,'Master Data'!$C$6)+SUMIFS('Order Details'!$Q:$Q,'Order Details'!$N:$N,Dashboard!$Q36,'Order Details'!$E:$E,"Yes",'Order Details'!$C:$C,'Master Data'!$C$7) -> 0 | S36: =SUMIFS('Order Details'!$O:$O,'Order Details'!$N:$N,Dashboard!$Q36,'Order Details'!$E:$E,"Yes",'Order Details'!$C:$C,'Master Data'!$C$4)+SUMIFS('Order Details'!$O:$O,'Order Details'!$N:$N,Dashboard!$Q36,'Order Details'!$E:$E,"Yes",'Order Details'!$C:$C,'Master Data'!$C$5)+SUMIFS('Order Details'!$O:$O,'Order Details'!$N:$N,Dashboard!$Q36,'Order Details'!$E:$E,"Yes",'Order Details'!$C:$C,'Master Data'!$C$6)+SUMIFS('Order Details'!$O:$O,'Order Details'!$N:$N,Dashboard!$Q36,'Order Details'!$E:$E,"Yes",'Order Details'!$C:$C,'Master Data'!$C$7) -> 0 | T36: =SUMIFS('Order Details'!$P:$P,'Order Details'!$N:$N,Dashboard!$Q36,'Order Details'!$E:$E,"Yes",'Order Details'!$C:$C,'Master Data'!$C$4)+SUMIFS('Order Details'!$P:$P,'Order Details'!$N:$N,Dashboard!$Q36,'Order Details'!$E:$E,"Yes",'Order Details'!$C:$C,'Master Data'!$C$5)+SUMIFS('Order Details'!$P:$P,'Order Details'!$N:$N,Dashboard!$Q36,'Order Details'!$E:$E,"Yes",'Order Details'!$C:$C,'Master Data'!$C$6)+SUMIFS('Order Details'!$P:$P,'Order Details'!$N:$N,Dashboard!$Q36,'Order Details'!$E:$E,"Yes",'Order Details'!$C:$C,'Master Data'!$C$7) -> 0 | U36: =SUMIFS('Order Details'!$V:$V,'Order Details'!$N:$N,Dashboard!$Q36,'Order Details'!$E:$E,"Yes",'Order Details'!$C:$C,'Master Data'!$C$4)+SUMIFS('Order Details'!$V:$V,'Order Details'!$N:$N,Dashboard!$Q36,'Order Details'!$E:$E,"Yes",'Order Details'!$C:$C,'Master Data'!$C$5)+SUMIFS('Order Details'!$V:$V,'Order Details'!$N:$N,Dashboard!$Q36,'Order Details'!$E:$E,"Yes",'Order Details'!$C:$C,'Master Data'!$C$6)+SUMIFS('Order Details'!$V:$V,'Order Details'!$N:$N,Dashboard!$Q36,'Order Details'!$E:$E,"Yes",'Order Details'!$C:$C,'Master Data'!$C$7) -> 0
... Q38: ASC 0126 BRANDY WINE | R38: =SUMIFS('Order Details'!$Q:$Q,'Order Details'!$N:$N,Dashboard!$Q38,'Order Details'!$E:$E,"Yes",'Order Details'!$C:$C,'Master Data'!$C$4)+SUMIFS('Order Details'!$Q:$Q,'Order Details'!$N:$N,Dashboard!$Q38,'Order Details'!$E:$E,"Yes",'Order Details'!$C:$C,'Master Data'!$C$5)+SUMIFS('Order Details'!$Q:$Q,'Order Details'!$N:$N,Dashboard!$Q38,'Order Details'!$E:$E,"Yes",'Order Details'!$C:$C,'Master Data'!$C$6)+SUMIFS('Order Details'!$Q:$Q,'Order Details'!$N:$N,Dashboard!$Q38,'Order Details'!$E:$E,"Yes",'Order Details'!$C:$C,'Master Data'!$C$7) -> 0 | S38: =SUMIFS('Order Details'!$O:$O,'Order Details'!$N:$N,Dashboard!$Q38,'Order Details'!$E:$E,"Yes",'Order Details'!$C:$C,'Master Data'!$C$4)+SUMIFS('Order Details'!$O:$O,'Order Details'!$N:$N,Dashboard!$Q38,'Order Details'!$E:$E,"Yes",'Order Details'!$C:$C,'Master Data'!$C$5)+SUMIFS('Order Details'!$O:$O,'Order Details'!$N:$N,Dashboard!$Q38,'Order Details'!$E:$E,"Yes",'Order Details'!$C:$C,'Master Data'!$C$6)+SUMIFS('Order Details'!$O:$O,'Order Details'!$N:$N,Dashboard!$Q38,'Order Details'!$E:$E,"Yes",'Order Details'!$C:$C,'Master Data'!$C$7) -> 0 | T38: =SUMIFS('Order Details'!$P:$P,'Order Details'!$N:$N,Dashboard!$Q38,'Order Details'!$E:$E,"Yes",'Order Details'!$C:$C,'Master Data'!$C$4)+SUMIFS('Order Details'!$P:$P,'Order Details'!$N:$N,Dashboard!$Q38,'Order Details'!$E:$E,"Yes",'Order Details'!$C:$C,'Master Data'!$C$5)+SUMIFS('Order Details'!$P:$P,'Order Details'!$N:$N,Dashboard!$Q38,'Order Details'!$E:$E,"Yes",'Order Details'!$C:$C,'Master Data'!$C$6)+SUMIFS('Order Details'!$P:$P,'Order Details'!$N:$N,Dashboard!$Q38,'Order Details'!$E:$E,"Yes",'Order Details'!$C:$C,'Master Data'!$C$7) -> 0 | U38: =SUMIFS('Order Details'!$V:$V,'Order Details'!$N:$N,Dashboard!$Q38,'Order Details'!$E:$E,"Yes",'Order Details'!$C:$C,'Master Data'!$C$4)+SUMIFS('Order Details'!$V:$V,'Order Details'!$N:$N,Dashboard!$Q38,'Order Details'!$E:$E,"Yes",'Order Details'!$C:$C,'Master Data'!$C$5)+SUMIFS('Order Details'!$V:$V,'Order Details'!$N:$N,Dashboard!$Q38,'Order Details'!$E:$E,"Yes",'Order Details'!$C:$C,'Master Data'!$C$6)+SUMIFS('Order Details'!$V:$V,'Order Details'!$N:$N,Dashboard!$Q38,'Order Details'!$E:$E,"Yes",'Order Details'!$C:$C,'Master Data'!$C$7) -> 0
Q39: TOTALS | R39: =SUM(R24:R38) -> 165100 | S39: =SUM(S24:S38) -> 5626.863 | T39: =SUM(T24:T38) -> 523244.49 | U39: =SUM(U24:U38) -> 4085714.3
Q42: VOLUME SHIPPED
Q43: COLORS (Purple are Standard Colors) | R43: Sheets | S43: MSF | T43: M2 | U43: $
Q44: ASC 0096 GLOSSY BLACK | R44: =R4-R24 -> 51000 | S44: =S4-S24 -> 1807.694 | T44: =T4-T24 -> 165508.06 | U44: =U4-U24 -> 1246274.3
Q45: ASC 0069 GLOSSY WHITE | R45: =R5-R25 -> 55750 | S45: =S5-S25 -> 1934.6853 | T45: =T5-T25 -> 179596.67 | U45: =U5-U25 -> 1353851.1
...

Sheet Item Summary
B2: BACKLOG (SHEETS) | Q2: SHIPPED (SHEETS)
B3: ITEM | D3: STOCKING LOCATION | Q3: ITEM | S3: STOCKING LOCATION
B4: Product Code | C4: Description | D4: South Paris, ME | E4: Ashburn, GA | F4: Hillsboro, TX | G4: Nampa, ID | H4: Granger, IN | I4: Gordon, PA | J4: Minneota, MN | K4: Houston, TX | L4: Twin Falls, ID | M4: Savannah, GA | N4: TOTALS | Q4: Product Code | R4: Description | S4: South Paris, ME | T4: Ashburn, GA | U4: Hillsboro, TX | V4: Nampa, ID | W4: Granger, IN | X4: Gordon, PA | Y4: Minneota, MN | Z4: Houston, TX | AA4: Twin Falls, ID | AB4: Savannah, GA | AC4: TOTALS
